<?xml version="1.0"?>
<robot name="myrobot" xmlns:xacro="http://ros.org/wiki/xacro"  >

<!-- PARAMETERS -->
	<xacro:property name="support_cote" value="0.028" />
	<xacro:property name="support_longueur" value="0.1" />

<!-- PARAMETERS --> <!-- Params arbitraires voir note post it -->
	<xacro:property name="corps_cote" value="0.028" />


<!-- PARAMETERS -->
	<xacro:property name="roue_epaisseur" value="0.04" />
	<xacro:property name="roue_rayon" value="0.08" /> 



	<xacro:macro name="roue_av" params="prefix support_x support_y support_z support_masse corps_masse roue_masse">

		<link name="support_roue_av_${prefix}">

		<visual name="support_roue_av_${prefix}_visual">
			<origin xyz="0 0 0" rpy="0 0 0"/>
			<geometry>
				<mesh filename="package://mybot_description/meshes/support_roue_av.dae"/>			
			</geometry>	    
		</visual>

		<collision name='collision'>
			<origin xyz="0 0 0" rpy=" 0 0 0"/>
			<geometry>
				<mesh filename="package://mybot_description/meshes/support_roue_av.dae"/>
			</geometry>
		</collision>

		<inertial>
			<origin xyz="0 0 0" rpy="0 0 0"/>
			<mass value="${support_masse}"/>
			<inertia 
				ixx="${(1/12)*support_masse*(support_longueur*support_longueur+support_cote*support_cote)}" 
				ixy="0.0" 
				ixz="0.0" 
				iyy="${(1/6)*support_masse*support_cote*support_cote}"
				iyz="0.0" 
				izz="${(1/12)*support_masse*(support_longueur*support_longueur+support_cote*support_cote)}"/>
		</inertial>
	</link>

	<joint name="joint_support_roue_av_${prefix}" type="fixed">
		<origin xyz="${support_x} ${support_y} ${support_z}" rpy="0 0 0"/> 
    	<axis xyz="0 0 0"/> 
		<parent link="base_link"/>
		<child link="support_roue_av_${prefix}"/>
	</joint>


		<link name="corps_roue_av_${prefix}">

		<visual name="corps_roue_av_${prefix}_visual">
			<origin xyz="0 0 0" rpy="0 0 0"/>
			<geometry>
				<mesh filename="package://mybot_description/meshes/corps_roue_av.dae"/>			
			</geometry>	    
		</visual>

	    <collision name='collision'>
			<origin xyz="0 0 0" rpy=" 0 0 0"/>
			<geometry>
				<mesh filename="package://mybot_description/meshes/corps_roue_av.dae"/>
			</geometry>
	    </collision>

		<inertial>
			<origin xyz="0 0 0" rpy="0 0 0"/>
			<mass value="${corps_masse}"/>
			<inertia 
				ixx="${(1/6.0)*corps_masse*corps_cote*corps_cote}"
				ixy="0.0" 
				ixz="0.0"
				iyy="${(1/6.0)*corps_masse*corps_cote*corps_cote}"
				iyz="0.0" 
				izz="${(1/6.0)*corps_masse*corps_cote*corps_cote}"/>
		</inertial>
	</link>

	<joint name="joint_corps_roue_av_${prefix}" type="continuous">
		<origin xyz="0 0 0" rpy="0 0 0"/> 
		<axis xyz="0 0 1"/> 
		<parent link="support_roue_av_${prefix}"/>
		<child link="corps_roue_av_${prefix}"/>
	    <!--limit effort="100" velocity="100"/>
	    <joint_properties damping="1000.0" friction="10000.0"/-->
	</joint>


	<link name="roue_av_${prefix}">

		<visual name="roue_av_${prefix}_visual">
			<origin xyz="0 0 0" rpy="0 0 0"/>
			<geometry>
				<mesh filename="package://mybot_description/meshes/roue_av.dae"/>			
			</geometry>	    
		</visual>

	    <collision name='collision'>
			<origin xyz="0 0 0" rpy=" 0 0 0"/>
			<geometry>
				<mesh filename="package://mybot_description/meshes/roue_av.dae"/>
			</geometry>
	    </collision>

		<inertial>
			<origin xyz="0 0 0" rpy="0 0 0"/>
			<mass value="${roue_masse}"/>
			<inertia 
				ixx="${(1/4)*roue_masse*roue_rayon*roue_rayon+(1/12)*roue_masse*roue_epaisseur*roue_epaisseur}" 
				ixy="0.0" 
				ixz="0.0" 
				iyy="${(1/2)*roue_masse*roue_rayon*roue_rayon}"
				iyz="0.0" 
				izz="${(1/4)*roue_masse*roue_rayon*roue_rayon+(1/12)*roue_masse*roue_epaisseur*roue_epaisseur}"/>
		</inertial>
	 </link>

		<joint name="joint_roue_av_${prefix}" type="continuous">
			<origin xyz="-0.05 0 -0.113" rpy="0 0 0"/>
			<axis xyz="0 1 0"/> 
			<parent link="corps_roue_av_${prefix}"/>
			<child link="roue_av_${prefix}"/>
		</joint>

	</xacro:macro>
</robot>

<!--
		<surface>
			<friction>
				<ode>
				    <mu1>0.9</mu1>
				    <mu2>0.9</mu2>
				    <kp>1000000.0</kp>
				    <kd>10.0</kd>            
				    <minDepth>0.001</minDepth>
				    <maxContacts>1</maxContacts>
				</ode>
			</friction>
		</surface>

		-->
